<?xml version="1.0"?>
<robot name="emu" xmlns:xacro="http://www.ros.org/wiki/xacro">
     <gazebo>
        <plugin name="gazebo_ros_control" filename="libgazebo_ros_control.so">
            <robotNamespace>/emu</robotNamespace>
        </plugin>
    </gazebo>
    <xacro:include filename="$(find emu_description)/urdf/emu.gazebo"/>
    <xacro:include filename="$(find emu_description)/urdf/camera.xacro"/>

    <xacro:emu_cam parent = "link_4" offset_from_parent = "0.0 0.109 0.444 " rotate_from_parent = "0 0 1.57075"/>

<!--=================== LINKS ========================-->
    <!-- <link name="world"/> -->

    <link name="base_link">
		<inertial>
			<origin xyz = "0.03581298 0.00000140 0.07057116"/>
			<mass value = "4.6883"/>
			<inertia ixx = "0.02107003" iyy = "0.04864817" izz = "0.05239187" ixy = "0.00000013" ixz = "0.0149951" iyz = "-0.00000032"/>
		</inertial>
        <collision> 
			<origin xyz="0 0 0"/> 
			<geometry> 
				<mesh filename="package://emu_description/meshes/collision/Base_link_c.STL" scale="1 1 1"/>
			</geometry> 
		</collision>
        <visual>
            <geometry>
                <mesh filename="package://emu_description/meshes/Base_link.STL" scale="1 1 1"/>
            </geometry>
            <material name="Grey">
                <color rgba="0.7 0.7 0.7 1"/>
            </material>
        </visual>
    </link>

    <link name="link_1">
		<inertial>
            <origin xyz = "0.04462098 -0.02110293 0.20827883"/>
			<mass value = "6.67642390"/>
            <inertia ixx = "0.05879639" iyy = "0.06029628" izz = "0.03519299" ixy = "0.00412696" ixz = "0.01915494" iyz = "-0.00070895"/>
		</inertial>
        <collision> 
			<origin xyz="0 0 0"/> 
			<geometry> 
				<mesh filename="package://emu_description/meshes/collision/Link1_c.STL" scale="1 1 1"/>
			</geometry> 
		</collision>
        <visual>
            <geometry>
                <mesh filename="package://emu_description/meshes/Link1.STL" scale="1 1 1"/>
            </geometry>
            <origin rpy="1.57075 0 0" xyz = "0.12596 0 0.30767"/>
            <material name="Grey">
                <color rgba="0.7 0.7 0.7 1"/>
            </material>
        </visual>
    </link>

    <link name="link_2">
		<inertial>
			<origin xyz = "-0.00010812 0.09578956 0.01003609"/>
			<mass value = "5.43224826"/>
			<inertia ixx = "0.07858891" iyy = "0.01308430" izz = "0.06958558" ixy = "-0.00005089" ixz = "-0.00003323" iyz = "0.01045852"/>
		</inertial>
        <collision> 
			<origin xyz="0 0 0"/> 
			<geometry> 
				<mesh filename="package://emu_description/meshes/collision/Link2_c.STL" scale="1 1 1"/>
			</geometry> 
		</collision>
        <visual>
            <geometry>
                <mesh filename="package://emu_description/meshes/Link2.STL" scale="1 1 1"/>
            </geometry>
            <origin rpy="0 0 1.57075" xyz = "0 0.4 0"/>
            <material name="Grey">
                <color rgba="0.7 0.7 0.7 1"/>
            </material>
        </visual>
    </link>

    <link name="link_3">
		<inertial>
			<origin xyz = "0.01157144 0.05910683 0.00781579"/>
			<mass value = "4.46265173"/>
			<inertia ixx = "0.09737261" iyy = "0.01098583" izz = "0.10341164" ixy = "-0.01155842" ixz = "-0.00013064" iyz = "-0.00161986"/>
		</inertial>
        <collision> 
			<origin xyz="0 0 0"/> 
			<geometry> 
				<mesh filename="package://emu_description/meshes/collision/Link3_c.STL" scale="1 1 1"/>
			</geometry> 
		</collision>
        <visual>
            <geometry>
                <mesh filename="package://emu_description/meshes/Link3.STL" scale="1 1 1"/>
            </geometry>
            <origin rpy="1.57075 0 0" xyz = "0.05 0 0"/>
            <material name="Grey">
                <color rgba="0.7 0.7 0.7 1"/>
            </material>
        </visual>
    </link>

    <link name="link_4">
		<inertial>
			<origin xyz = "-0.00169590 0.01339008 0.39616334"/>
			<mass value = "1.17365091"/>
			<inertia ixx = "0.00585017" iyy = "0.00363604" izz = "0.00356846" ixy = " -0.00019968" ixz = "-0.00009573" iyz = "0.00079386"/>
		</inertial>
        <collision> 
			<origin xyz="0 0 0"/> 
			<geometry> 
				<mesh filename="package://emu_description/meshes/collision/Link4_c.STL" scale="1 1 1"/>
			</geometry> 
		</collision>
        <visual>
            <geometry>
                <mesh filename="package://emu_description/meshes/Link4.STL" scale="1 1 1"/>
            </geometry>
            <origin rpy="-1.57075 0 0" xyz = "0 0 0.466"/>
            <material name="Grey">
                <color rgba="0.7 0.7 0.7 1"/>
            </material>
        </visual>
    </link>

    <link name="link_5">
		<inertial>
			<origin xyz = "0 0 0"/>
			<mass value = "0.51"/>
			<inertia ixx = "0" iyy = "0" izz = "0" ixy = "0" ixz = "0" iyz = "0"/>
		</inertial>
        <collision> 
			<origin xyz="0 0 0"/> 
			<geometry> 
				<mesh filename="package://emu_description/meshes/collision/Link5_c.STL" scale="1 1 1"/>
			</geometry> 
		</collision>
        <visual>
            <geometry>
                <mesh filename="package://emu_description/meshes/Link5.STL" scale="1 1 1"/>
            </geometry>
            <origin rpy="1.57075 0 0" xyz = "0 0 0"/>
            <material name="Grey">
                <color rgba="0.7 0.7 0.7 1"/>
            </material>
        </visual>
    </link>

    <link name="link_6">
		<inertial>
			<origin xyz = "-0.00016738 0 0.04413320"/>
			<mass value = "0.43864195"/>
			<inertia ixx = "0.00049965" iyy = "0.00043225" izz = "0.00020871" ixy = "0" ixz = "-0.00000204" iyz = "0"/>
		</inertial>
        <collision> 
			<origin xyz="0 0 0"/> 
			<geometry> 
				<mesh filename="package://emu_description/meshes/Link6.STL" scale="1 1 1"/>
			</geometry> 
		</collision>
        <visual>
            <geometry>
                <mesh filename="package://emu_description/meshes/Link6.STL" scale="1 1 1"/>
            </geometry>
            <material name="Grey">
                <color rgba="0.7 0.7 0.7 1"/>
            </material>
        </visual>
    </link>

    <link name="tool_base">
		<inertial>
			<origin xyz = "-0.00016738 0 0.04413320"/>
			<mass value = "0.43864195"/>
			<inertia ixx = "0.00049965" iyy = "0.00043225" izz = "0.00020871" ixy = "0" ixz = "-0.00000204" iyz = "0"/>
		</inertial>
        <collision> 
			<origin xyz="0 0 0"/> 
			<geometry> 
				<mesh filename="package://emu_description/meshes/tool_static.STL" scale="1 1 1"/>
			</geometry> 
		</collision>
        <visual>
            <geometry>
                <mesh filename="package://emu_description/meshes/tool_static.STL" scale="1 1 1"/>
            </geometry>
            <material name="Grey">
                <color rgba="0.7 0.7 0.7 1"/>
            </material>
        </visual>
    </link>

    
    <link name="sliding_jaw">
        <collision> 
			<origin xyz="0 0 0"/> 
			<geometry> 
				<mesh filename="package://emu_description/meshes/tool_sliding.STL" scale="1 1 1"/>
			</geometry> 
		</collision>
        <visual>
            <geometry>
                <mesh filename="package://emu_description/meshes/tool_sliding.STL" scale="1 1 1"/>
            </geometry>
            <material name="Grey">
                <color rgba="0.7 0.7 0.7 1"/>
            </material>
        </visual>
    </link>

    <link name="grasp_frame"/>

    <link name="suction_frame"/>
<!--=================== JOINTS ========================-->

    <!-- <joint name="world_to_base" type="fixed">
        <parent link="world"/>
        <child link="base_link"/>
        <origin xyz = "0 0 0.001"/>
    </joint> -->

    <joint name="joint_1" type="revolute">
        <parent link="base_link"/>
        <child link="link_1"/>
        <axis xyz = "0 0 1"/>
        <limit lower = "-3.1066" upper = "3.1066" effort = "1000" velocity = "2.5" acceleration = "1"/>
        <dynamics damping="0.1"/>
    </joint>

    <joint name="joint_2" type="revolute">
        <parent link="link_1"/>
        <child link="link_2"/>
        <axis xyz = "0 0 1"/>
        <limit lower = "-2.917" upper = "1.703" effort = "1000" velocity = "1.5" acceleration = "1"/>
        <origin rpy="1.57075 0 0" xyz = "0.12596 0 0.30767"/>
        <dynamics damping="0.1"/>
    </joint>

    <joint name="joint_3" type="revolute">
        <parent link="link_2"/>
        <child link="link_3"/>
        <axis xyz = "0 0 1"/>
        <limit lower = "-1.4312" upper = "4.1190" effort = "1000" velocity = "2.5" acceleration = "1"/>
        <origin rpy="0 0 1.57075" xyz = "0 0.4 0"/>
        <dynamics damping="0.1"/>
    </joint>

    <joint name="joint_4" type="revolute">
        <parent link="link_3"/>
        <child link="link_4"/>
        <axis xyz = "0 0 1"/>
        <limit lower = "-3.1067" upper = "3.1067" effort = "1000" velocity = "1.5" acceleration = "2"/>
        <origin rpy="1.57075 0 0" xyz = "0.05 0 0"/>
        <dynamics damping="0.03"/>
    </joint>

    <joint name="joint_5" type="revolute">
        <parent link="link_4"/>
        <child link="link_5"/>
        <axis xyz = "0 0 1"/>
        <limit lower = "-3.1067" upper = "3.1067" effort = "1000" velocity = "2" acceleration = "2"/>
        <origin rpy="-1.57075 0 0" xyz = "0 0 0.466"/>
        <dynamics damping="0.01"/>
    </joint>

    <joint name="joint_6" type="revolute">
        <parent link="link_5"/>
        <child link="link_6"/>
        <axis xyz = "0 0 1"/>
        <limit lower = "-3.1067" upper = "3.1067" effort = "50" velocity = "2" acceleration = "2"/>
        <origin rpy="1.57075 0 0" xyz = "0 -0.043 0"/>
        <!-- <origin rpy="1.57075 0 0" xyz = "0 0 0"/> -->
        <dynamics damping="0"/>
    </joint>

    <joint name="joint_6_to_tool_base" type="fixed">
        <parent link="link_6"/>
        <child link="tool_base"/>
        <origin rpy="0 0 0" xyz = "0 0 0"/>
    </joint>

    <joint name="sliding_jaw_joint" type="prismatic">
        <parent link="tool_base"/>
        <child link="sliding_jaw"/>
        <axis xyz = "0 0 1"/>
        <limit lower = "0" upper = "0.0715" effort = "10" velocity = "5" acceleration = "10"/>
        <origin rpy="1.57075 0 0" xyz = "0 0.0288 0.145"/>
    </joint>

    <joint name="grasp_frame_transform" type="fixed">
        <parent link="tool_base"/>
        <child link="grasp_frame"/>
        <axis xyz = "0 0 1"/>
        <origin rpy="0 0 0" xyz = "0 0 0.145"/>
    </joint>

    <joint name="suction_frame_transform" type="fixed">
        <parent link="tool_base"/>
        <child link="suction_frame"/>
        <axis xyz = "0 0 1"/>
        <origin rpy="0 0 0" xyz = "0 -0.0881 0.1852"/>
    </joint>

    <transmission name="tran1">
        <type>transmission_interface/SimpleTransmission</type>
        <joint name="joint_1">
            <hardwareInterface>hardware_interface/EffortJointInterface</hardwareInterface>
        </joint>
        <actuator name="motor1">
            <hardwareInterface>hardware_interface/EffortJointInterface</hardwareInterface>
            <mechanicalReduction>1</mechanicalReduction>
        </actuator>
    </transmission>

    <transmission name="tran2">
        <type>transmission_interface/SimpleTransmission</type>
        <joint name="joint_2">
            <hardwareInterface>hardware_interface/EffortJointInterface</hardwareInterface>
        </joint>
        <actuator name="motor2">
            <hardwareInterface>hardware_interface/EffortJointInterface</hardwareInterface>
            <mechanicalReduction>1</mechanicalReduction>
        </actuator>
    </transmission>

    <transmission name="tran3">
        <type>transmission_interface/SimpleTransmission</type>
        <joint name="joint_3">
            <hardwareInterface>hardware_interface/EffortJointInterface</hardwareInterface>
        </joint>
        <actuator name="motor3">
            <hardwareInterface>hardware_interface/EffortJointInterface</hardwareInterface>
            <mechanicalReduction>1</mechanicalReduction>
        </actuator>
    </transmission>

    <transmission name="tran4">
        <type>transmission_interface/SimpleTransmission</type>
        <joint name="joint_4">
            <hardwareInterface>hardware_interface/EffortJointInterface</hardwareInterface>
        </joint>
        <actuator name="motor4">
            <hardwareInterface>hardware_interface/EffortJointInterface</hardwareInterface>
            <mechanicalReduction>1</mechanicalReduction>
        </actuator>
    </transmission>

    <transmission name="tran5">
        <type>transmission_interface/SimpleTransmission</type>
        <joint name="joint_5">
            <hardwareInterface>hardware_interface/EffortJointInterface</hardwareInterface>
        </joint>
        <actuator name="motor5">
            <hardwareInterface>hardware_interface/EffortJointInterface</hardwareInterface>
            <mechanicalReduction>1</mechanicalReduction>
        </actuator>
    </transmission>

    <transmission name="tran6">
        <type>transmission_interface/SimpleTransmission</type>
        <joint name="joint_6">
            <hardwareInterface>hardware_interface/EffortJointInterface</hardwareInterface>
        </joint>
        <actuator name="motor6">
            <hardwareInterface>hardware_interface/EffortJointInterface</hardwareInterface>
            <mechanicalReduction>1</mechanicalReduction>
        </actuator>
    </transmission>

</robot>